<?xml version='1.0'?>
<sdf version='1.3'>
  <model name="Jurek">
    <!-- <static>true</static> -->
    <link name='chassis'>
      <inertial>
      	<mass>
      	  1000
      	</mass>
      </inertial>
      <collision name='collision'>
	<pose>0 0 0.6 0 0 0</pose>
	<geometry>
	  <box>
	    <size>1 1 1</size>
	  </box>
	</geometry>
      </collision>

      <visual name='visual'>
	<pose>0 0 0.6 0 0 0</pose>
	<geometry>
	  <box>
	    <size>1 1 1</size>
	  </box>
	</geometry>

	<!-- <pose>0 0 0 0 0 0</pose> -->
	<!-- <cast_shadows>0</cast_shadows> -->
	<!-- <geometry> -->
	<!--   <mesh> -->
	<!--     <uri>model://jurek/yaris_body_r.dae</uri> -->
	<!--     <scale>0.04 0.04 0.04</scale> -->
	<!--   </mesh> -->
	<!-- </geometry> -->
      </visual>
    </link>

    <link name="rear_left_wheel">
      <inertial>
    	<mass>
	  10
    	</mass>
      </inertial>
      <pose>0.81 1.20 .3 0 -1.5707 0</pose>
      <collision name="collision">
	<geometry>
	  <cylinder>
	    <radius>.3</radius>
	    <length>.185</length>
	  </cylinder>
	</geometry>
	<surface>
	  <friction>
	    <ode>
	      <mu>0.5</mu>
	    </ode>
	  </friction>
	</surface>
      </collision>
      <visual name="visual">
	<pose>0 0 0.05 0 0 0</pose>
	<cast_shadows>0</cast_shadows>
	<geometry>
	  <cylinder>
	    <radius>.3</radius>
	    <length>.185</length>
	  </cylinder>
	  <!-- <mesh> -->
	  <!--   <uri>model://jurek/yaris_wheel.dae</uri> -->
	  <!--   <scale>0.04 0.04 0.04</scale> -->
	  <!-- </mesh> -->
	</geometry>
      </visual>
    </link>

    <link name="rear_right_wheel">
      <inertial>
    	<mass>
	  10
    	</mass>
      </inertial>
      <pose>-0.81 1.20 .3 0 1.5707 3.14159</pose>
      <collision name="collision">
	<geometry>
	  <cylinder>
	    <radius>.3</radius>
	    <length>.185</length>
	  </cylinder>
	</geometry>
	<surface>
	  <friction>
	    <ode>
	      <mu>0.5</mu>
	    </ode>
	  </friction>
	</surface>
      </collision>
      <visual name="visual">
	<pose>0 0 -.05  0 0 0</pose>
	<cast_shadows>0</cast_shadows>
	<geometry> 
	  <cylinder>
	    <radius>.3</radius>
	    <length>.185</length>
	  </cylinder>
	  <!-- <mesh> -->
	  <!--   <uri>model://jurek/yaris_wheel.dae</uri> -->
	  <!--   <scale>0.04 0.04 0.04</scale> -->
	  <!-- </mesh> -->
	</geometry>
      </visual>
    </link>

    <link name="front_left_wheel">
      <inertial>
    	<mass>
	  10
    	</mass>
      </inertial>
      <pose>0.81 -1.20 .3 0 -1.5707 0</pose>
      <collision name="collision">
	<geometry>
	  <cylinder>
	    <radius>.3</radius>
	    <length>.185</length>
	  </cylinder>
	</geometry>
	<surface>
	  <friction>
	    <ode>
	      <mu>0.5</mu>
	    </ode>
	  </friction>
	</surface>
      </collision>
      <visual name="visual">
	<pose>0 0 0.05 0 0 0</pose>
	<cast_shadows>0</cast_shadows>
	<geometry>
	  <cylinder>
	    <radius>.3</radius>
	    <length>.185</length>
	  </cylinder>
	  <!-- <mesh> -->
	  <!--   <uri>model://jurek/yaris_wheel.dae</uri> -->
	  <!--   <scale>0.04 0.04 0.04</scale> -->
	  <!-- </mesh> -->
	</geometry>
      </visual>
    </link>

    <link name="front_right_wheel">
      <inertial>
    	<mass>
	  10
    	</mass>
      </inertial>
      <pose>-0.81 -1.20 .3 0 1.5707 3.14159</pose>
      <collision name="collision">
	<geometry>
	  <cylinder>
	    <radius>.3</radius>
	    <length>.185</length>
	  </cylinder>
	</geometry>
	<surface>
	  <friction>
	    <ode>
	      <mu>0.5</mu>
	    </ode>
	  </friction>
	</surface>
      </collision>
      <visual name="visual">
	<pose>0 0 -.05  0 0 0</pose>
	<cast_shadows>0</cast_shadows>
	<geometry>
	  <cylinder>
	    <radius>.3</radius>
	    <length>.185</length>
	  </cylinder>
	  <!-- <mesh> -->
	  <!--   <uri>model://jurek/yaris_wheel.dae</uri> -->
	  <!--   <scale>0.04 0.04 0.04</scale> -->
	  <!-- </mesh> -->
	</geometry>
      </visual>
    </link>

    <joint type="revolute2" name="front_left_wheel_hinge">
      <pose>0 0 0 0 0 0</pose>
      <child>front_left_wheel</child>
      <parent>chassis</parent>
      <axis>
	<xyz>0 0 1</xyz>
	<!-- <limit> -->
    	<!--   <upper>0.611</upper> -->
    	<!--   <lower>-0.611</lower> -->
    	<!-- </limit> -->
      </axis>
      <axis2>
	<xyz>1 0 0</xyz>
      </axis2>
    </joint>

    <joint type="revolute2" name="front_right_wheel_hinge">
      <pose>0 0 0 0 0 0</pose>
      <child>front_right_wheel</child>
      <parent>chassis</parent>
      <axis>
	<xyz>0 0 1</xyz>
	<!-- <limit> -->
    	<!--   <upper>0.611</upper> -->
    	<!--   <lower>-0.611</lower> -->
    	<!-- </limit> -->
      </axis>
      <axis2>
	<xyz>1 0 0</xyz>
	
      </axis2>
    </joint>

    <joint type="revolute" name="rear_left_wheel_hinge">
      <pose>0 0 0 0 0 0</pose>
      <child>rear_left_wheel</child>
      <parent>chassis</parent>
      <axis>
	<xyz>1 0 0</xyz>
      </axis>
    </joint>

    <joint type="revolute" name="rear_right_wheel_hinge">
      <pose>0 0 0 0 0 0</pose>
      <child>rear_right_wheel</child>
      <parent>chassis</parent>
      <axis>
	<xyz>1 0 0</xyz>
      </axis>
    </joint>

<!--kamera-->

   <include>
      <uri>model://camera</uri>
      <pose>0 0 1.49 0 0.05 -1.5707</pose>
    </include>
    <joint name="camera_joint" type="revolute">
      <child>camera::link</child>
      <parent>chassis</parent>
      <axis>
	<xyz>0 0 1</xyz>
	<limit>
	  <upper>0</upper>
	  <lower>0</lower>
	</limit>
      </axis>
    </joint>

<!--kamera koniec-->



    <!-- <include> -->
    <!--   <uri>model://camera</uri> -->
    <!--   <pose>0.2 0 0.2 0 0 0</pose> -->
    <!-- </include> -->

    <!-- <joint name="camera_joint" type="revolute"> -->
    <!--   <child>camera::link</child> -->
    <!--   <parent>chassis</parent> -->
    <!--   <axis> -->
    <!-- 	<xyz>0 0 1</xyz> -->
    <!-- <limit> -->
    <!--   <upper>0</upper> -->
    <!--   <lower>0</lower> -->
    <!-- </limit> -->
    <!--   </axis> -->
    <!-- </joint> -->

    <plugin filename="/home/paw/od bart/my_plugin/build/libmy_plugin.so" name="my_plugin">
      <left_wheel_hinge>front_left_wheel_hinge</left_wheel_hinge>
      <right_wheel_hinge>front_right_wheel_hinge</right_wheel_hinge>
      <camera_sensor>camera</camera_sensor>
    </plugin>

  </model>
</sdf>

